2025-03-24 18:35:57|ERROR   |root                            |Error trying to get releases from Github. Connection Error.|'Traceback (most recent call last):\n  File "/app/bazarr/bin/bazarr/../libs/urllib3/connection.py", line 198, in _new_conn\n    sock = connection.create_connection(\n           ^^^^^^^^^^^^^^^^^^^^^^^^^^^^^\n  File "/app/bazarr/bin/bazarr/../libs/urllib3/util/connection.py", line 60, in create_connection\n    for res in socket.getaddrinfo(host, port, family, socket.SOCK_STREAM):\n               ^^^^^^^^^^^^^^^^^^^^^^^^^^^^^^^^^^^^^^^^^^^^^^^^^^^^^^^^^^\n  File "/usr/lib/python3.12/socket.py", line 978, in getaddrinfo\n    for res in _socket.getaddrinfo(host, port, family, type, proto, flags):\n               ^^^^^^^^^^^^^^^^^^^^^^^^^^^^^^^^^^^^^^^^^^^^^^^^^^^^^^^^^^^\nsocket.gaierror: [Errno -2] Name does not resolve\n\nThe above exception was the direct cause of the following exception:\n\nTraceback (most recent call last):\n  File "/app/bazarr/bin/bazarr/../libs/urllib3/connectionpool.py", line 793, in urlopen\n    response = self._make_request(\n               ^^^^^^^^^^^^^^^^^^^\n  File "/app/bazarr/bin/bazarr/../libs/urllib3/connectionpool.py", line 491, in _make_request\n    raise new_e\n  File "/app/bazarr/bin/bazarr/../libs/urllib3/connectionpool.py", line 467, in _make_request\n    self._validate_conn(conn)\n  File "/app/bazarr/bin/bazarr/../libs/urllib3/connectionpool.py", line 1099, in _validate_conn\n    conn.connect()\n  File "/app/bazarr/bin/bazarr/../libs/urllib3/connection.py", line 616, in connect\n    self.sock = sock = self._new_conn()\n                       ^^^^^^^^^^^^^^^^\n  File "/app/bazarr/bin/bazarr/../libs/urllib3/connection.py", line 205, in _new_conn\n    raise NameResolutionError(self.host, self, e) from e\nurllib3.exceptions.NameResolutionError: <urllib3.connection.HTTPSConnection object at 0x7ef70b4b0b30>: Failed to resolve \'api.github.com\' ([Errno -2] Name does not resolve)\n\nThe above exception was the direct cause of the following exception:\n\nTraceback (most recent call last):\n  File "/app/bazarr/bin/bazarr/../libs/requests/adapters.py", line 486, in send\n    resp = conn.urlopen(\n           ^^^^^^^^^^^^^\n  File "/app/bazarr/bin/bazarr/../libs/urllib3/connectionpool.py", line 847, in urlopen\n    retries = retries.increment(\n              ^^^^^^^^^^^^^^^^^^\n  File "/app/bazarr/bin/bazarr/../libs/urllib3/util/retry.py", line 515, in increment\n    raise MaxRetryError(_pool, url, reason) from reason  # type: ignore[arg-type]\n    ^^^^^^^^^^^^^^^^^^^^^^^^^^^^^^^^^^^^^^^^^^^^^^^^^^^\nurllib3.exceptions.MaxRetryError: HTTPSConnectionPool(host=\'api.github.com\', port=443): Max retries exceeded with url: /repos/morpheus65535/Bazarr/releases?per_page=100 (Caused by NameResolutionError("<urllib3.connection.HTTPSConnection object at 0x7ef70b4b0b30>: Failed to resolve \'api.github.com\' ([Errno -2] Name does not resolve)"))\n\nDuring handling of the above exception, another exception occurred:\n\nTraceback (most recent call last):\n  File "/app/bazarr/bin/bazarr/app/check_update.py", line 28, in check_releases\n    r = requests.get(url_releases, allow_redirects=True, timeout=15)\n        ^^^^^^^^^^^^^^^^^^^^^^^^^^^^^^^^^^^^^^^^^^^^^^^^^^^^^^^^^^^^\n  File "/app/bazarr/bin/bazarr/../libs/requests/api.py", line 73, in get\n    return request("get", url, params=params, **kwargs)\n           ^^^^^^^^^^^^^^^^^^^^^^^^^^^^^^^^^^^^^^^^^^^^\n  File "/app/bazarr/bin/bazarr/../libs/requests/api.py", line 59, in request\n    return session.request(method=method, url=url, **kwargs)\n           ^^^^^^^^^^^^^^^^^^^^^^^^^^^^^^^^^^^^^^^^^^^^^^^^^\n  File "/app/bazarr/bin/bazarr/../libs/requests/sessions.py", line 589, in request\n    resp = self.send(prep, **send_kwargs)\n           ^^^^^^^^^^^^^^^^^^^^^^^^^^^^^^\n  File "/app/bazarr/bin/bazarr/../libs/requests/sessions.py", line 703, in send\n    r = adapter.send(request, **kwargs)\n        ^^^^^^^^^^^^^^^^^^^^^^^^^^^^^^^\n  File "/app/bazarr/bin/bazarr/../libs/requests/adapters.py", line 519, in send\n    raise ConnectionError(e, request=request)\nrequests.exceptions.ConnectionError: HTTPSConnectionPool(host=\'api.github.com\', port=443): Max retries exceeded with url: /repos/morpheus65535/Bazarr/releases?per_page=100 (Caused by NameResolutionError("<urllib3.connection.HTTPSConnection object at 0x7ef70b4b0b30>: Failed to resolve \'api.github.com\' ([Errno -2] Name does not resolve)"))'|
2025-03-24 18:35:58|ERROR   |root                            |Error trying to get releases from Github. Connection Error.|'Traceback (most recent call last):\n  File "/app/bazarr/bin/bazarr/../libs/urllib3/connection.py", line 198, in _new_conn\n    sock = connection.create_connection(\n           ^^^^^^^^^^^^^^^^^^^^^^^^^^^^^\n  File "/app/bazarr/bin/bazarr/../custom_libs/subliminal_patch/http.py", line 325, in patched_create_connection\n    return _orig_create_connection(address, *args, **kwargs)\n           ^^^^^^^^^^^^^^^^^^^^^^^^^^^^^^^^^^^^^^^^^^^^^^^^^\n  File "/app/bazarr/bin/bazarr/../libs/urllib3/util/connection.py", line 60, in create_connection\n    for res in socket.getaddrinfo(host, port, family, socket.SOCK_STREAM):\n               ^^^^^^^^^^^^^^^^^^^^^^^^^^^^^^^^^^^^^^^^^^^^^^^^^^^^^^^^^^\n  File "/usr/lib/python3.12/socket.py", line 978, in getaddrinfo\n    for res in _socket.getaddrinfo(host, port, family, type, proto, flags):\n               ^^^^^^^^^^^^^^^^^^^^^^^^^^^^^^^^^^^^^^^^^^^^^^^^^^^^^^^^^^^\nsocket.gaierror: [Errno -2] Name does not resolve\n\nThe above exception was the direct cause of the following exception:\n\nTraceback (most recent call last):\n  File "/app/bazarr/bin/bazarr/../libs/urllib3/connectionpool.py", line 793, in urlopen\n    response = self._make_request(\n               ^^^^^^^^^^^^^^^^^^^\n  File "/app/bazarr/bin/bazarr/../libs/urllib3/connectionpool.py", line 491, in _make_request\n    raise new_e\n  File "/app/bazarr/bin/bazarr/../libs/urllib3/connectionpool.py", line 467, in _make_request\n    self._validate_conn(conn)\n  File "/app/bazarr/bin/bazarr/../libs/urllib3/connectionpool.py", line 1099, in _validate_conn\n    conn.connect()\n  File "/app/bazarr/bin/bazarr/../libs/urllib3/connection.py", line 616, in connect\n    self.sock = sock = self._new_conn()\n                       ^^^^^^^^^^^^^^^^\n  File "/app/bazarr/bin/bazarr/../libs/urllib3/connection.py", line 205, in _new_conn\n    raise NameResolutionError(self.host, self, e) from e\nurllib3.exceptions.NameResolutionError: <urllib3.connection.HTTPSConnection object at 0x7ef6dc616150>: Failed to resolve \'api.github.com\' ([Errno -2] Name does not resolve)\n\nThe above exception was the direct cause of the following exception:\n\nTraceback (most recent call last):\n  File "/app/bazarr/bin/bazarr/../libs/requests/adapters.py", line 486, in send\n    resp = conn.urlopen(\n           ^^^^^^^^^^^^^\n  File "/app/bazarr/bin/bazarr/../libs/urllib3/connectionpool.py", line 847, in urlopen\n    retries = retries.increment(\n              ^^^^^^^^^^^^^^^^^^\n  File "/app/bazarr/bin/bazarr/../libs/urllib3/util/retry.py", line 515, in increment\n    raise MaxRetryError(_pool, url, reason) from reason  # type: ignore[arg-type]\n    ^^^^^^^^^^^^^^^^^^^^^^^^^^^^^^^^^^^^^^^^^^^^^^^^^^^\nurllib3.exceptions.MaxRetryError: HTTPSConnectionPool(host=\'api.github.com\', port=443): Max retries exceeded with url: /repos/morpheus65535/Bazarr/releases?per_page=100 (Caused by NameResolutionError("<urllib3.connection.HTTPSConnection object at 0x7ef6dc616150>: Failed to resolve \'api.github.com\' ([Errno -2] Name does not resolve)"))\n\nDuring handling of the above exception, another exception occurred:\n\nTraceback (most recent call last):\n  File "/app/bazarr/bin/bazarr/app/check_update.py", line 28, in check_releases\n    r = requests.get(url_releases, allow_redirects=True, timeout=15)\n        ^^^^^^^^^^^^^^^^^^^^^^^^^^^^^^^^^^^^^^^^^^^^^^^^^^^^^^^^^^^^\n  File "/app/bazarr/bin/bazarr/../libs/requests/api.py", line 73, in get\n    return request("get", url, params=params, **kwargs)\n           ^^^^^^^^^^^^^^^^^^^^^^^^^^^^^^^^^^^^^^^^^^^^\n  File "/app/bazarr/bin/bazarr/../libs/requests/api.py", line 59, in request\n    return session.request(method=method, url=url, **kwargs)\n           ^^^^^^^^^^^^^^^^^^^^^^^^^^^^^^^^^^^^^^^^^^^^^^^^^\n  File "/app/bazarr/bin/bazarr/../libs/requests/sessions.py", line 589, in request\n    resp = self.send(prep, **send_kwargs)\n           ^^^^^^^^^^^^^^^^^^^^^^^^^^^^^^\n  File "/app/bazarr/bin/bazarr/../libs/requests/sessions.py", line 703, in send\n    r = adapter.send(request, **kwargs)\n        ^^^^^^^^^^^^^^^^^^^^^^^^^^^^^^^\n  File "/app/bazarr/bin/bazarr/../libs/requests/adapters.py", line 519, in send\n    raise ConnectionError(e, request=request)\nrequests.exceptions.ConnectionError: HTTPSConnectionPool(host=\'api.github.com\', port=443): Max retries exceeded with url: /repos/morpheus65535/Bazarr/releases?per_page=100 (Caused by NameResolutionError("<urllib3.connection.HTTPSConnection object at 0x7ef6dc616150>: Failed to resolve \'api.github.com\' ([Errno -2] Name does not resolve)"))'|
2025-03-24 18:36:00|INFO    |waitress                        |BAZARR is started and waiting for requests on: http://***.***.***.***:6767|
2025-03-24 18:36:00|INFO    |waitress                        |BAZARR is started and waiting for requests on: http://[::]:6767|
2025-03-24 18:59:46|ERROR   |root                            |Error trying to get releases from Github. Connection Error.|'Traceback (most recent call last):\n  File "/app/bazarr/bin/bazarr/../libs/urllib3/connection.py", line 198, in _new_conn\n    sock = connection.create_connection(\n           ^^^^^^^^^^^^^^^^^^^^^^^^^^^^^\n  File "/app/bazarr/bin/bazarr/../libs/urllib3/util/connection.py", line 60, in create_connection\n    for res in socket.getaddrinfo(host, port, family, socket.SOCK_STREAM):\n               ^^^^^^^^^^^^^^^^^^^^^^^^^^^^^^^^^^^^^^^^^^^^^^^^^^^^^^^^^^\n  File "/usr/lib/python3.12/socket.py", line 978, in getaddrinfo\n    for res in _socket.getaddrinfo(host, port, family, type, proto, flags):\n               ^^^^^^^^^^^^^^^^^^^^^^^^^^^^^^^^^^^^^^^^^^^^^^^^^^^^^^^^^^^\nsocket.gaierror: [Errno -2] Name does not resolve\n\nThe above exception was the direct cause of the following exception:\n\nTraceback (most recent call last):\n  File "/app/bazarr/bin/bazarr/../libs/urllib3/connectionpool.py", line 793, in urlopen\n    response = self._make_request(\n               ^^^^^^^^^^^^^^^^^^^\n  File "/app/bazarr/bin/bazarr/../libs/urllib3/connectionpool.py", line 491, in _make_request\n    raise new_e\n  File "/app/bazarr/bin/bazarr/../libs/urllib3/connectionpool.py", line 467, in _make_request\n    self._validate_conn(conn)\n  File "/app/bazarr/bin/bazarr/../libs/urllib3/connectionpool.py", line 1099, in _validate_conn\n    conn.connect()\n  File "/app/bazarr/bin/bazarr/../libs/urllib3/connection.py", line 616, in connect\n    self.sock = sock = self._new_conn()\n                       ^^^^^^^^^^^^^^^^\n  File "/app/bazarr/bin/bazarr/../libs/urllib3/connection.py", line 205, in _new_conn\n    raise NameResolutionError(self.host, self, e) from e\nurllib3.exceptions.NameResolutionError: <urllib3.connection.HTTPSConnection object at 0x775f407f0d70>: Failed to resolve \'api.github.com\' ([Errno -2] Name does not resolve)\n\nThe above exception was the direct cause of the following exception:\n\nTraceback (most recent call last):\n  File "/app/bazarr/bin/bazarr/../libs/requests/adapters.py", line 486, in send\n    resp = conn.urlopen(\n           ^^^^^^^^^^^^^\n  File "/app/bazarr/bin/bazarr/../libs/urllib3/connectionpool.py", line 847, in urlopen\n    retries = retries.increment(\n              ^^^^^^^^^^^^^^^^^^\n  File "/app/bazarr/bin/bazarr/../libs/urllib3/util/retry.py", line 515, in increment\n    raise MaxRetryError(_pool, url, reason) from reason  # type: ignore[arg-type]\n    ^^^^^^^^^^^^^^^^^^^^^^^^^^^^^^^^^^^^^^^^^^^^^^^^^^^\nurllib3.exceptions.MaxRetryError: HTTPSConnectionPool(host=\'api.github.com\', port=443): Max retries exceeded with url: /repos/morpheus65535/Bazarr/releases?per_page=100 (Caused by NameResolutionError("<urllib3.connection.HTTPSConnection object at 0x775f407f0d70>: Failed to resolve \'api.github.com\' ([Errno -2] Name does not resolve)"))\n\nDuring handling of the above exception, another exception occurred:\n\nTraceback (most recent call last):\n  File "/app/bazarr/bin/bazarr/app/check_update.py", line 28, in check_releases\n    r = requests.get(url_releases, allow_redirects=True, timeout=15)\n        ^^^^^^^^^^^^^^^^^^^^^^^^^^^^^^^^^^^^^^^^^^^^^^^^^^^^^^^^^^^^\n  File "/app/bazarr/bin/bazarr/../libs/requests/api.py", line 73, in get\n    return request("get", url, params=params, **kwargs)\n           ^^^^^^^^^^^^^^^^^^^^^^^^^^^^^^^^^^^^^^^^^^^^\n  File "/app/bazarr/bin/bazarr/../libs/requests/api.py", line 59, in request\n    return session.request(method=method, url=url, **kwargs)\n           ^^^^^^^^^^^^^^^^^^^^^^^^^^^^^^^^^^^^^^^^^^^^^^^^^\n  File "/app/bazarr/bin/bazarr/../libs/requests/sessions.py", line 589, in request\n    resp = self.send(prep, **send_kwargs)\n           ^^^^^^^^^^^^^^^^^^^^^^^^^^^^^^\n  File "/app/bazarr/bin/bazarr/../libs/requests/sessions.py", line 703, in send\n    r = adapter.send(request, **kwargs)\n        ^^^^^^^^^^^^^^^^^^^^^^^^^^^^^^^\n  File "/app/bazarr/bin/bazarr/../libs/requests/adapters.py", line 519, in send\n    raise ConnectionError(e, request=request)\nrequests.exceptions.ConnectionError: HTTPSConnectionPool(host=\'api.github.com\', port=443): Max retries exceeded with url: /repos/morpheus65535/Bazarr/releases?per_page=100 (Caused by NameResolutionError("<urllib3.connection.HTTPSConnection object at 0x775f407f0d70>: Failed to resolve \'api.github.com\' ([Errno -2] Name does not resolve)"))'|
2025-03-24 18:59:47|ERROR   |root                            |Error trying to get releases from Github. Connection Error.|'Traceback (most recent call last):\n  File "/app/bazarr/bin/bazarr/../libs/urllib3/connection.py", line 198, in _new_conn\n    sock = connection.create_connection(\n           ^^^^^^^^^^^^^^^^^^^^^^^^^^^^^\n  File "/app/bazarr/bin/bazarr/../custom_libs/subliminal_patch/http.py", line 325, in patched_create_connection\n    return _orig_create_connection(address, *args, **kwargs)\n           ^^^^^^^^^^^^^^^^^^^^^^^^^^^^^^^^^^^^^^^^^^^^^^^^^\n  File "/app/bazarr/bin/bazarr/../libs/urllib3/util/connection.py", line 60, in create_connection\n    for res in socket.getaddrinfo(host, port, family, socket.SOCK_STREAM):\n               ^^^^^^^^^^^^^^^^^^^^^^^^^^^^^^^^^^^^^^^^^^^^^^^^^^^^^^^^^^\n  File "/usr/lib/python3.12/socket.py", line 978, in getaddrinfo\n    for res in _socket.getaddrinfo(host, port, family, type, proto, flags):\n               ^^^^^^^^^^^^^^^^^^^^^^^^^^^^^^^^^^^^^^^^^^^^^^^^^^^^^^^^^^^\nsocket.gaierror: [Errno -2] Name does not resolve\n\nThe above exception was the direct cause of the following exception:\n\nTraceback (most recent call last):\n  File "/app/bazarr/bin/bazarr/../libs/urllib3/connectionpool.py", line 793, in urlopen\n    response = self._make_request(\n               ^^^^^^^^^^^^^^^^^^^\n  File "/app/bazarr/bin/bazarr/../libs/urllib3/connectionpool.py", line 491, in _make_request\n    raise new_e\n  File "/app/bazarr/bin/bazarr/../libs/urllib3/connectionpool.py", line 467, in _make_request\n    self._validate_conn(conn)\n  File "/app/bazarr/bin/bazarr/../libs/urllib3/connectionpool.py", line 1099, in _validate_conn\n    conn.connect()\n  File "/app/bazarr/bin/bazarr/../libs/urllib3/connection.py", line 616, in connect\n    self.sock = sock = self._new_conn()\n                       ^^^^^^^^^^^^^^^^\n  File "/app/bazarr/bin/bazarr/../libs/urllib3/connection.py", line 205, in _new_conn\n    raise NameResolutionError(self.host, self, e) from e\nurllib3.exceptions.NameResolutionError: <urllib3.connection.HTTPSConnection object at 0x775f111c6ba0>: Failed to resolve \'api.github.com\' ([Errno -2] Name does not resolve)\n\nThe above exception was the direct cause of the following exception:\n\nTraceback (most recent call last):\n  File "/app/bazarr/bin/bazarr/../libs/requests/adapters.py", line 486, in send\n    resp = conn.urlopen(\n           ^^^^^^^^^^^^^\n  File "/app/bazarr/bin/bazarr/../libs/urllib3/connectionpool.py", line 847, in urlopen\n    retries = retries.increment(\n              ^^^^^^^^^^^^^^^^^^\n  File "/app/bazarr/bin/bazarr/../libs/urllib3/util/retry.py", line 515, in increment\n    raise MaxRetryError(_pool, url, reason) from reason  # type: ignore[arg-type]\n    ^^^^^^^^^^^^^^^^^^^^^^^^^^^^^^^^^^^^^^^^^^^^^^^^^^^\nurllib3.exceptions.MaxRetryError: HTTPSConnectionPool(host=\'api.github.com\', port=443): Max retries exceeded with url: /repos/morpheus65535/Bazarr/releases?per_page=100 (Caused by NameResolutionError("<urllib3.connection.HTTPSConnection object at 0x775f111c6ba0>: Failed to resolve \'api.github.com\' ([Errno -2] Name does not resolve)"))\n\nDuring handling of the above exception, another exception occurred:\n\nTraceback (most recent call last):\n  File "/app/bazarr/bin/bazarr/app/check_update.py", line 28, in check_releases\n    r = requests.get(url_releases, allow_redirects=True, timeout=15)\n        ^^^^^^^^^^^^^^^^^^^^^^^^^^^^^^^^^^^^^^^^^^^^^^^^^^^^^^^^^^^^\n  File "/app/bazarr/bin/bazarr/../libs/requests/api.py", line 73, in get\n    return request("get", url, params=params, **kwargs)\n           ^^^^^^^^^^^^^^^^^^^^^^^^^^^^^^^^^^^^^^^^^^^^\n  File "/app/bazarr/bin/bazarr/../libs/requests/api.py", line 59, in request\n    return session.request(method=method, url=url, **kwargs)\n           ^^^^^^^^^^^^^^^^^^^^^^^^^^^^^^^^^^^^^^^^^^^^^^^^^\n  File "/app/bazarr/bin/bazarr/../libs/requests/sessions.py", line 589, in request\n    resp = self.send(prep, **send_kwargs)\n           ^^^^^^^^^^^^^^^^^^^^^^^^^^^^^^\n  File "/app/bazarr/bin/bazarr/../libs/requests/sessions.py", line 703, in send\n    r = adapter.send(request, **kwargs)\n        ^^^^^^^^^^^^^^^^^^^^^^^^^^^^^^^\n  File "/app/bazarr/bin/bazarr/../libs/requests/adapters.py", line 519, in send\n    raise ConnectionError(e, request=request)\nrequests.exceptions.ConnectionError: HTTPSConnectionPool(host=\'api.github.com\', port=443): Max retries exceeded with url: /repos/morpheus65535/Bazarr/releases?per_page=100 (Caused by NameResolutionError("<urllib3.connection.HTTPSConnection object at 0x775f111c6ba0>: Failed to resolve \'api.github.com\' ([Errno -2] Name does not resolve)"))'|
2025-03-24 18:59:48|ERROR   |root                            |BAZARR cannot bind to specified TCP port, trying with default (6767)|'Traceback (most recent call last):\n  File "/app/bazarr/bin/bazarr/app/server.py", line 46, in configure_server\n    self.server = create_server(app,\n                  ^^^^^^^^^^^^^^^^^^\n  File "/app/bazarr/bin/bazarr/../libs/waitress/server.py", line 78, in create_server\n    last_serv = TcpWSGIServer(\n                ^^^^^^^^^^^^^^\n  File "/app/bazarr/bin/bazarr/../libs/waitress/server.py", line 243, in __init__\n    self.bind_server_socket()\n  File "/app/bazarr/bin/bazarr/../libs/waitress/server.py", line 364, in bind_server_socket\n    self.bind(sockaddr)\n  File "/app/bazarr/bin/bazarr/../libs/waitress/wasyncore.py", line 395, in bind\n    return self.socket.bind(addr)\n           ^^^^^^^^^^^^^^^^^^^^^^\nOSError: [Errno 98] Address in use'|
2025-03-24 18:59:49|ERROR   |root                            |BAZARR cannot bind to default TCP port (6767) because it's already in use, exiting...|'Traceback (most recent call last):\n  File "/app/bazarr/bin/bazarr/app/server.py", line 46, in configure_server\n    self.server = create_server(app,\n                  ^^^^^^^^^^^^^^^^^^\n  File "/app/bazarr/bin/bazarr/../libs/waitress/server.py", line 78, in create_server\n    last_serv = TcpWSGIServer(\n                ^^^^^^^^^^^^^^\n  File "/app/bazarr/bin/bazarr/../libs/waitress/server.py", line 243, in __init__\n    self.bind_server_socket()\n  File "/app/bazarr/bin/bazarr/../libs/waitress/server.py", line 364, in bind_server_socket\n    self.bind(sockaddr)\n  File "/app/bazarr/bin/bazarr/../libs/waitress/wasyncore.py", line 395, in bind\n    return self.socket.bind(addr)\n           ^^^^^^^^^^^^^^^^^^^^^^\nOSError: [Errno 98] Address in use'|
